### Description of Issue/Question
We are unable to add/modify entries in LDAP using state.ldap since upgrade to 2018.3.0
Everything is working fine when we rollback to salt 2017.7.5+ds-1


### Setup
Content of the state file:
```
ldap_roles_groups:
  ldap.managed:
    - connect_spec:
       url: {{ ldap_url }}
       bind:
         method: simple
         dn: {{ ldap_dn }}
         password: {{ ldap_password }}
    - entries:
      {% for group in ldap['groups'] %}
      - '{{ group.fqdn }}':
        - default:
            objectClass:
              - group
              - top
            cn:
              - {{ group.name }}
            name:
              - {{ group.name }}
            sAMAccountName:
              - {{ group.name }}
      {% endfor %}
```

Returned error:
```          ID: ldap_roles_groups
    Function: ldap.managed
      Result: False
     Comment: An exception occurred in this state: Traceback (most recent call last):
                File "/usr/lib/python2.7/dist-packages/salt/state.py", line 1878, in call
                  **cdata['kwargs'])
                File "/usr/lib/python2.7/dist-packages/salt/loader.py", line 1823, in wrapper
                  return f(*args, **kwargs)
                File "/usr/lib/python2.7/dist-packages/salt/states/ldap.py", line 334, in managed
                  __salt__['ldap3.add'](l, dn, n)
                File "/usr/lib/python2.7/dist-packages/salt/modules/ldap3.py", line 412, in add
                  l.c.add_s(dn, modlist)
                File "/usr/lib/python2.7/dist-packages/ldap/ldapobject.py", line 209, in add_s
                  msgid = self.add(dn,modlist)
                File "/usr/lib/python2.7/dist-packages/ldap/ldapobject.py", line 206, in add
                  return self.add_ext(dn,modlist,None,None)
                File "/usr/lib/python2.7/dist-packages/ldap/ldapobject.py", line 191, in add_ext
                  return self._ldap_call(self._l.add_ext,dn,modlist,RequestControlTuples(serverctrls),RequestControlTuples(clientctrls))
                File "/usr/lib/python2.7/dist-packages/ldap/ldapobject.py", line 106, in _ldap_call
                  result = func(*args,**kwargs)
              TypeError: ('expected a string in the list', u'group')
     Started: 09:02:00.034829
    Duration: 51.893 ms
     Changes:
```

### Steps to Reproduce Issue


### Versions Report
```Salt Version:
           Salt: 2018.3.0

Dependency Versions:
           cffi: 1.5.2
       cherrypy: Not Installed
       dateutil: 2.4.2
      docker-py: 1.9.0
          gitdb: 0.6.4
      gitpython: 1.0.1
          ioflo: Not Installed
         Jinja2: 2.8
        libgit2: 0.24.0
        libnacl: Not Installed
       M2Crypto: Not Installed
           Mako: 1.0.3
   msgpack-pure: Not Installed
 msgpack-python: 0.4.6
   mysql-python: Not Installed
      pycparser: 2.14
       pycrypto: 2.6.1
   pycryptodome: Not Installed
         pygit2: 0.24.0
         Python: 2.7.12 (default, Dec  4 2017, 14:50:18)
   python-gnupg: Not Installed
         PyYAML: 3.11
          PyZMQ: 15.2.0
           RAET: Not Installed
          smmap: 0.9.0
        timelib: Not Installed
        Tornado: 4.2.1
            ZMQ: 4.1.4

System Versions:
           dist: Ubuntu 16.04 xenial
         locale: UTF-8
        machine: x86_64
        release: 4.4.0-1054-aws
         system: Linux
        version: Ubuntu 16.04 xenial
```