I get the error below when trying to create a new user. Also included is my .sls:

``` yaml
haproxy:
  pkg:
    - installed
  service:
    - running
    - enable: True
    - config: /etc/rc.conf.local
    - reload: True
    - require:
      - pkg: haproxy
      - user: haproxy-user
    - watch:
      - file: /usr/local/etc/haproxy.conf

haproxy-user:
  user:
    - present
    - name: haproxy

/usr/local/etc/haproxy.conf:
  file.managed:
    - source: salt://haproxy/haproxy.conf
    - template: jinja
    - context:
      listen: {{ salt['network.ip_addrs']('lo1')[0] }}

----------
    State: - user
    Name:      haproxy
    Function:  present
        Result:    False
        Comment:   An exception occurred in this state: Traceback (most recent call last):
  File "/usr/local/lib/python2.7/site-packages/salt/state.py", line 1239, in call
    ret = self.states[cdata['full']](*cdata['args'])
  File "/usr/local/lib/python2.7/site-packages/salt/states/user.py", line 367, in present
    createhome=createhome):
  File "/usr/local/lib/python2.7/site-packages/salt/modules/pw_user.py", line 79, in add
    raise TypeError('Invalid keyword argument(s): {}'.format(kwargs))
TypeError: Invalid keyword argument(s): {'createhome': True}
```
